<?xml version="1.0" ?>
<!-- =================================================================================== -->
<!-- |    This document was autogenerated by xacro from assy2urdf.xacro                | -->
<!-- |    EDITING THIS FILE BY HAND IS NOT RECOMMENDED                                 | -->
<!-- =================================================================================== -->
<robot name="assy2urdf">
  <material name="silver">
    <color rgba="0.700 0.700 0.700 1.000"/>
  </material>
  <transmission name="Revolute 2_tran">
    <type>transmission_interface/SimpleTransmission</type>
    <joint name="Revolute 2">
      <hardwareInterface>hardware_interface/EffortJointInterface</hardwareInterface>
    </joint>
    <actuator name="Revolute 2_actr">
      <hardwareInterface>hardware_interface/EffortJointInterface</hardwareInterface>
      <mechanicalReduction>1</mechanicalReduction>
    </actuator>
  </transmission>
  <transmission name="Revolute 4_tran">
    <type>transmission_interface/SimpleTransmission</type>
    <joint name="Revolute 4">
      <hardwareInterface>hardware_interface/EffortJointInterface</hardwareInterface>
    </joint>
    <actuator name="Revolute 4_actr">
      <hardwareInterface>hardware_interface/EffortJointInterface</hardwareInterface>
      <mechanicalReduction>1</mechanicalReduction>
    </actuator>
  </transmission>
  <transmission name="Revolute 6_tran">
    <type>transmission_interface/SimpleTransmission</type>
    <joint name="Revolute 6">
      <hardwareInterface>hardware_interface/EffortJointInterface</hardwareInterface>
    </joint>
    <actuator name="Revolute 6_actr">
      <hardwareInterface>hardware_interface/EffortJointInterface</hardwareInterface>
      <mechanicalReduction>1</mechanicalReduction>
    </actuator>
  </transmission>
  <transmission name="Revolute 8_tran">
    <type>transmission_interface/SimpleTransmission</type>
    <joint name="Revolute 8">
      <hardwareInterface>hardware_interface/EffortJointInterface</hardwareInterface>
    </joint>
    <actuator name="Revolute 8_actr">
      <hardwareInterface>hardware_interface/EffortJointInterface</hardwareInterface>
      <mechanicalReduction>1</mechanicalReduction>
    </actuator>
  </transmission>
  <transmission name="Revolute 10_tran">
    <type>transmission_interface/SimpleTransmission</type>
    <joint name="Revolute 10">
      <hardwareInterface>hardware_interface/EffortJointInterface</hardwareInterface>
    </joint>
    <actuator name="Revolute 10_actr">
      <hardwareInterface>hardware_interface/EffortJointInterface</hardwareInterface>
      <mechanicalReduction>1</mechanicalReduction>
    </actuator>
  </transmission>
  <transmission name="Revolute 12_tran">
    <type>transmission_interface/SimpleTransmission</type>
    <joint name="Revolute 12">
      <hardwareInterface>hardware_interface/EffortJointInterface</hardwareInterface>
    </joint>
    <actuator name="Revolute 12_actr">
      <hardwareInterface>hardware_interface/EffortJointInterface</hardwareInterface>
      <mechanicalReduction>1</mechanicalReduction>
    </actuator>
  </transmission>
  <gazebo>
    <plugin filename="libgazebo_ros_control.so" name="control"/>
  </gazebo>
  <gazebo reference="base_link">
    <material>Gazebo/Silver</material>
    <mu1>0.2</mu1>
    <mu2>0.2</mu2>
    <self_collide>true</self_collide>
    <gravity>true</gravity>
  </gazebo>
  <gazebo reference="XM,H-430_idler_Component5_v1_1">
    <material>Gazebo/Silver</material>
    <mu1>0.2</mu1>
    <mu2>0.2</mu2>
    <self_collide>true</self_collide>
  </gazebo>
  <gazebo reference="piper_01_v1_1">
    <material>Gazebo/Silver</material>
    <mu1>0.2</mu1>
    <mu2>0.2</mu2>
    <self_collide>true</self_collide>
  </gazebo>
  <gazebo reference="XM,H-430_idler_Component5_v1__1__1">
    <material>Gazebo/Silver</material>
    <mu1>0.2</mu1>
    <mu2>0.2</mu2>
    <self_collide>true</self_collide>
  </gazebo>
  <gazebo reference="piper_02_v1_1">
    <material>Gazebo/Silver</material>
    <mu1>0.2</mu1>
    <mu2>0.2</mu2>
    <self_collide>true</self_collide>
  </gazebo>
  <gazebo reference="XM,H-430_idler_Component5_v1__5__1">
    <material>Gazebo/Silver</material>
    <mu1>0.2</mu1>
    <mu2>0.2</mu2>
    <self_collide>true</self_collide>
  </gazebo>
  <gazebo reference="piper_03_v1_1">
    <material>Gazebo/Silver</material>
    <mu1>0.2</mu1>
    <mu2>0.2</mu2>
    <self_collide>true</self_collide>
  </gazebo>
  <gazebo reference="XM,H-430_idler_Component5_v1__4__1">
    <material>Gazebo/Silver</material>
    <mu1>0.2</mu1>
    <mu2>0.2</mu2>
    <self_collide>true</self_collide>
  </gazebo>
  <gazebo reference="piper_04_v2_1">
    <material>Gazebo/Silver</material>
    <mu1>0.2</mu1>
    <mu2>0.2</mu2>
    <self_collide>true</self_collide>
  </gazebo>
  <gazebo reference="XM,H-430_idler_Component5_v1__2__1">
    <material>Gazebo/Silver</material>
    <mu1>0.2</mu1>
    <mu2>0.2</mu2>
    <self_collide>true</self_collide>
  </gazebo>
  <gazebo reference="piper_05_v1_1">
    <material>Gazebo/Silver</material>
    <mu1>0.2</mu1>
    <mu2>0.2</mu2>
    <self_collide>true</self_collide>
  </gazebo>
  <gazebo reference="XM,H-430_idler_Component5_v1__3__1">
    <material>Gazebo/Silver</material>
    <mu1>0.2</mu1>
    <mu2>0.2</mu2>
    <self_collide>true</self_collide>
  </gazebo>
  <gazebo reference="gripper_01_v1_1">
    <material>Gazebo/Silver</material>
    <mu1>0.2</mu1>
    <mu2>0.2</mu2>
    <self_collide>true</self_collide>
  </gazebo>
  <link name="base_link">
    <inertial>
      <origin rpy="0 0 0" xyz="2.7473517341654513e-16 0.00036006507840164056 0.021846353644801978"/>
      <mass value="0.8118244367701402"/>
      <inertia ixx="0.000649" ixy="0.0" ixz="0.0" iyy="0.000558" iyz="-3e-06" izz="0.000561"/>
    </inertial>
    <visual>
      <origin rpy="0 0 0" xyz="0 0 0"/>
      <geometry>
        <mesh filename="package://gravity_compensation/meshes/base_link.stl" scale="0.001 0.001 0.001"/>
      </geometry>
      <material name="silver"/>
    </visual>
    <collision>
      <origin rpy="0 0 0" xyz="0 0 0"/>
      <geometry>
        <mesh filename="package://gravity_compensation/meshes/base_link.stl" scale="0.001 0.001 0.001"/>
      </geometry>
    </collision>
  </link>
  <link name="XM,H-430_idler_Component5_v1_1">
    <inertial>
      <origin rpy="0 0 0" xyz="-0.014249999999995681 -0.007727783469295217 0.00678328400293815"/>
      <mass value="0.082"/>
      <inertia ixx="9.2e-05" ixy="-0.0" ixz="-0.0" iyy="5.3e-05" iyz="-1e-06" izz="8.2e-05"/>
    </inertial>
    <visual>
      <origin rpy="0 0 0" xyz="-0.0145 -0.008134 -0.054"/>
      <geometry>
        <mesh filename="package://gravity_compensation/meshes/XM,H-430_idler_Component5_v1_1.stl" scale="0.001 0.001 0.001"/>
      </geometry>
      <material name="silver"/>
    </visual>
    <collision>
      <origin rpy="0 0 0" xyz="-0.0145 -0.008134 -0.054"/>
      <geometry>
        <mesh filename="package://gravity_compensation/meshes/XM,H-430_idler_Component5_v1_1.stl" scale="0.001 0.001 0.001"/>
      </geometry>
    </collision>
  </link>
  <link name="piper_01_v1_1">
    <inertial>
      <origin rpy="0 0 0" xyz="-4.174178364069192e-18 -2.2457508828607753e-07 0.009032474778675595"/>
      <mass value="0.01447"/>
      <inertia ixx="4.5e-05" ixy="-0.0" ixz="-0.0" iyy="5.5e-05" iyz="0.0" izz="8.3e-05"/>
    </inertial>
    <visual>
      <origin rpy="0 0 0" xyz="-0.00025 -0.012134 -0.079"/>
      <geometry>
        <mesh filename="package://gravity_compensation/meshes/piper_01_v1_1.stl" scale="0.001 0.001 0.001"/>
      </geometry>
      <material name="silver"/>
    </visual>
    <collision>
      <origin rpy="0 0 0" xyz="-0.00025 -0.012134 -0.079"/>
      <geometry>
        <mesh filename="package://gravity_compensation/meshes/piper_01_v1_1.stl" scale="0.001 0.001 0.001"/>
      </geometry>
    </collision>
  </link>
  <link name="XM,H-430_idler_Component5_v1__1__1">
    <inertial>
      <origin rpy="0 0 0" xyz="0.005216715997061845 0.014249775424885845 0.016272441105814592"/>
      <mass value="0.082"/>
      <inertia ixx="8.2e-05" ixy="-0.0" ixz="1e-06" iyy="9.2e-05" iyz="0.0" izz="5.3e-05"/>
    </inertial>
    <visual>
      <origin rpy="0 0 0" xyz="0.00575 0.002366 -0.09425"/>
      <geometry>
        <mesh filename="package://gravity_compensation/meshes/XM,H-430_idler_Component5_v1__1__1.stl" scale="0.001 0.001 0.001"/>
      </geometry>
      <material name="silver"/>
    </visual>
    <collision>
      <origin rpy="0 0 0" xyz="0.00575 0.002366 -0.09425"/>
      <geometry>
        <mesh filename="package://gravity_compensation/meshes/XM,H-430_idler_Component5_v1__1__1.stl" scale="0.001 0.001 0.001"/>
      </geometry>
    </collision>
  </link>
  <link name="piper_02_v1_1">
    <inertial>
      <origin rpy="0 0 0" xyz="-0.021431679375501177 -2.2961620577653663e-07 0.0692772686697884"/>
      <mass value="0.048"/>
      <inertia ixx="0.001868" ixy="-0.0" ixz="6.6e-05" iyy="0.001887" iyz="-0.0" izz="0.000151"/>
    </inertial>
    <visual>
      <origin rpy="0 0 0" xyz="0.01875 -0.011884 -0.12225"/>
      <geometry>
        <mesh filename="package://gravity_compensation/meshes/piper_02_v1_1.stl" scale="0.001 0.001 0.001"/>
      </geometry>
      <material name="silver"/>
    </visual>
    <collision>
      <origin rpy="0 0 0" xyz="0.01875 -0.011884 -0.12225"/>
      <geometry>
        <mesh filename="package://gravity_compensation/meshes/piper_02_v1_1.stl" scale="0.001 0.001 0.001"/>
      </geometry>
    </collision>
  </link>
  <link name="XM,H-430_idler_Component5_v1__5__1">
    <inertial>
      <origin rpy="0 0 0" xyz="-0.005216715997061777 0.014249775424894487 0.016272441105814495"/>
      <mass value="0.082"/>
      <inertia ixx="8.2e-05" ixy="-0.0" ixz="-1e-06" iyy="9.2e-05" iyz="-0.0" izz="5.3e-05"/>
    </inertial>
    <visual>
      <origin rpy="0 0 0" xyz="0.036251 0.002616 -0.2545"/>
      <geometry>
        <mesh filename="package://gravity_compensation/meshes/XM,H-430_idler_Component5_v1__5__1.stl" scale="0.001 0.001 0.001"/>
      </geometry>
      <material name="silver"/>
    </visual>
    <collision>
      <origin rpy="0 0 0" xyz="0.036251 0.002616 -0.2545"/>
      <geometry>
        <mesh filename="package://gravity_compensation/meshes/XM,H-430_idler_Component5_v1__5__1.stl" scale="0.001 0.001 0.001"/>
      </geometry>
    </collision>
  </link>
  <link name="piper_03_v1_1">
    <inertial>
      <origin rpy="0 0 0" xyz="0.023006962403644977 -2.169044674045495e-07 0.05048311262320321"/>
      <mass value="0.03698"/>
      <inertia ixx="0.000875" ixy="-0.0" ixz="-9.5e-05" iyy="0.000943" iyz="0.0" izz="0.000193"/>
    </inertial>
    <visual>
      <origin rpy="0 0 0" xyz="0.023251 -0.011634 -0.2825"/>
      <geometry>
        <mesh filename="package://gravity_compensation/meshes/piper_03_v1_1.stl" scale="0.001 0.001 0.001"/>
      </geometry>
      <material name="silver"/>
    </visual>
    <collision>
      <origin rpy="0 0 0" xyz="0.023251 -0.011634 -0.2825"/>
      <geometry>
        <mesh filename="package://gravity_compensation/meshes/piper_03_v1_1.stl" scale="0.001 0.001 0.001"/>
      </geometry>
    </collision>
  </link>
  <link name="XM,H-430_idler_Component5_v1__4__1">
    <inertial>
      <origin rpy="0 0 0" xyz="-0.016272441105814675 0.01424977542489448 0.006783284002937928"/>
      <mass value="0.082"/>
      <inertia ixx="5.3e-05" ixy="0.0" ixz="1e-06" iyy="9.2e-05" iyz="-0.0" izz="8.2e-05"/>
    </inertial>
    <visual>
      <origin rpy="0 0 0" xyz="-0.0225 0.002866 -0.3785"/>
      <geometry>
        <mesh filename="package://gravity_compensation/meshes/XM,H-430_idler_Component5_v1__4__1.stl" scale="0.001 0.001 0.001"/>
      </geometry>
      <material name="silver"/>
    </visual>
    <collision>
      <origin rpy="0 0 0" xyz="-0.0225 0.002866 -0.3785"/>
      <geometry>
        <mesh filename="package://gravity_compensation/meshes/XM,H-430_idler_Component5_v1__4__1.stl" scale="0.001 0.001 0.001"/>
      </geometry>
    </collision>
  </link>
  <link name="piper_04_v2_1">
    <inertial>
      <origin rpy="0 0 0" xyz="-1.0495077029659683e-16 -2.245751316437561e-07 0.009099644951418073"/>
      <mass value="0.0163"/>
      <inertia ixx="4.4e-05" ixy="-0.0" ixz="-0.0" iyy="5.5e-05" iyz="-0.0" izz="8.3e-05"/>
    </inertial>
    <visual>
      <origin rpy="0 0 0" xyz="0.0055 -0.011384 -0.4035"/>
      <geometry>
        <mesh filename="package://gravity_compensation/meshes/piper_04_v2_1.stl" scale="0.001 0.001 0.001"/>
      </geometry>
      <material name="silver"/>
    </visual>
    <collision>
      <origin rpy="0 0 0" xyz="0.0055 -0.011384 -0.4035"/>
      <geometry>
        <mesh filename="package://gravity_compensation/meshes/piper_04_v2_1.stl" scale="0.001 0.001 0.001"/>
      </geometry>
    </collision>
  </link>
  <link name="XM,H-430_idler_Component5_v1__2__1">
    <inertial>
      <origin rpy="0 0 0" xyz="-0.005216715997061833 0.014249775424894383 0.016272441105814495"/>
      <mass value="0.082"/>
      <inertia ixx="8.2e-05" ixy="-0.0" ixz="-1e-06" iyy="9.2e-05" iyz="-0.0" izz="5.3e-05"/>
    </inertial>
    <visual>
      <origin rpy="0 0 0" xyz="-0.0005 0.003116 -0.41875"/>
      <geometry>
        <mesh filename="package://gravity_compensation/meshes/XM,H-430_idler_Component5_v1__2__1.stl" scale="0.001 0.001 0.001"/>
      </geometry>
      <material name="silver"/>
    </visual>
    <collision>
      <origin rpy="0 0 0" xyz="-0.0005 0.003116 -0.41875"/>
      <geometry>
        <mesh filename="package://gravity_compensation/meshes/XM,H-430_idler_Component5_v1__2__1.stl" scale="0.001 0.001 0.001"/>
      </geometry>
    </collision>
  </link>
  <link name="piper_05_v1_1">
    <inertial>
      <origin rpy="0 0 0" xyz="0.014503212167685133 -2.2457508234638435e-07 -5.551115123125783e-17"/>
      <mass value="0.0163"/>
      <inertia ixx="8.5e-05" ixy="0.0" ixz="0.0" iyy="5.9e-05" iyz="0.0" izz="4.8e-05"/>
    </inertial>
    <visual>
      <origin rpy="0 0 0" xyz="-0.0135 -0.011134 -0.44675"/>
      <geometry>
        <mesh filename="package://gravity_compensation/meshes/piper_05_v1_1.stl" scale="0.001 0.001 0.001"/>
      </geometry>
      <material name="silver"/>
    </visual>
    <collision>
      <origin rpy="0 0 0" xyz="-0.0135 -0.011134 -0.44675"/>
      <geometry>
        <mesh filename="package://gravity_compensation/meshes/piper_05_v1_1.stl" scale="0.001 0.001 0.001"/>
      </geometry>
    </collision>
  </link>
  <link name="XM,H-430_idler_Component5_v1__3__1">
    <inertial>
      <origin rpy="0 0 0" xyz="0.016272441105814973 0.014249775424887489 -0.005216715997061971"/>
      <mass value="0.082"/>
      <inertia ixx="5.3e-05" ixy="0.0" ixz="-1e-06" iyy="9.2e-05" iyz="0.0" izz="8.2e-05"/>
    </inertial>
    <visual>
      <origin rpy="0 0 0" xyz="-0.03525 0.003366 -0.45275"/>
      <geometry>
        <mesh filename="package://gravity_compensation/meshes/XM,H-430_idler_Component5_v1__3__1.stl" scale="0.001 0.001 0.001"/>
      </geometry>
      <material name="silver"/>
    </visual>
    <collision>
      <origin rpy="0 0 0" xyz="-0.03525 0.003366 -0.45275"/>
      <geometry>
        <mesh filename="package://gravity_compensation/meshes/XM,H-430_idler_Component5_v1__3__1.stl" scale="0.001 0.001 0.001"/>
      </geometry>
    </collision>
  </link>
  <link name="gripper_01_v1_1">
    <inertial>
      <origin rpy="0 0 0" xyz="0.016022982911055098 0.012131219692872446 0.02194263457401119"/>
      <mass value="0.036"/>
      <inertia ixx="0.000469" ixy="-0.000236" ixz="0.000119" iyy="0.000447" iyz="0.000105" izz="0.000655"/>
    </inertial>
    <visual>
      <origin rpy="0 0 0" xyz="-0.06325 -0.010884 -0.46575"/>
      <geometry>
        <mesh filename="package://gravity_compensation/meshes/gripper_01_v1_1.stl" scale="0.001 0.001 0.001"/>
      </geometry>
      <material name="silver"/>
    </visual>
    <collision>
      <origin rpy="0 0 0" xyz="-0.06325 -0.010884 -0.46575"/>
      <geometry>
        <mesh filename="package://gravity_compensation/meshes/gripper_01_v1_1.stl" scale="0.001 0.001 0.001"/>
      </geometry>
    </collision>
  </link>
  <joint name="Rigid 1" type="fixed">
    <origin rpy="0 0 0" xyz="0.0145 0.008134 0.054"/>
    <parent link="base_link"/>
    <child link="XM,H-430_idler_Component5_v1_1"/>
  </joint>
  <joint name="Revolute 2" type="revolute">
    <limit lower="-1.57" upper="1.57" effort="10" velocity="3"/>
    <origin rpy="0 0 0" xyz="-0.01425 0.004 0.025"/>
    <parent link="XM,H-430_idler_Component5_v1_1"/>
    <child link="piper_01_v1_1"/>
    <axis xyz="0.0 0.0 1.0"/>
  </joint>
  <joint name="Rigid 3" type="fixed">
    <origin rpy="0 0 0" xyz="-0.006 -0.0145 0.01525"/>
    <parent link="piper_01_v1_1"/>
    <child link="XM,H-430_idler_Component5_v1__1__1"/>
  </joint>
  <joint name="Revolute 4" type="revolute">
    <limit lower="-3" upper="3" effort="10" velocity="3"/>
    <origin rpy="0 0 0" xyz="-0.013 0.01425 0.028"/>
    <parent link="XM,H-430_idler_Component5_v1__1__1"/>
    <child link="piper_02_v1_1"/>
    <axis xyz="-1.0 0.0 0.0"/>
  </joint>
  <joint name="Rigid 5" type="fixed">
    <origin rpy="0 0 0" xyz="-0.017501 -0.0145 0.13225"/>
    <parent link="piper_02_v1_1"/>
    <child link="XM,H-430_idler_Component5_v1__5__1"/>
  </joint>
  <joint name="Revolute 6" type="revolute">
    <limit lower="-3" upper="3" effort="10" velocity="3"/>
    <origin rpy="0 0 0" xyz="0.013 0.01425 0.028"/>
    <parent link="XM,H-430_idler_Component5_v1__5__1"/>
    <child link="piper_03_v1_1"/>
    <axis xyz="1.0 0.0 -0.0"/>
  </joint>
  <joint name="Rigid 7" type="fixed">
    <origin rpy="0 0 0" xyz="0.045751 -0.0145 0.096"/>
    <parent link="piper_03_v1_1"/>
    <child link="XM,H-430_idler_Component5_v1__4__1"/>
  </joint>
  <joint name="Revolute 8" type="revolute">
    <limit lower="-1.57" upper="1.57" effort="10" velocity="3"/>
    <origin rpy="0 0 0" xyz="-0.028 0.01425 0.025"/>
    <parent link="XM,H-430_idler_Component5_v1__4__1"/>
    <child link="piper_04_v2_1"/>
    <axis xyz="-0.0 -0.0 1.0"/>
  </joint>
  <joint name="Rigid 9" type="fixed">
    <origin rpy="0 0 0" xyz="0.006 -0.0145 0.01525"/>
    <parent link="piper_04_v2_1"/>
    <child link="XM,H-430_idler_Component5_v1__2__1"/>
  </joint>
  <joint name="Revolute 10" type="revolute">
    <limit lower="-1.57" upper="1.57" effort="10" velocity="3"/>
    <origin rpy="0 0 0" xyz="0.013 0.01425 0.028"/>
    <parent link="XM,H-430_idler_Component5_v1__2__1"/>
    <child link="piper_05_v1_1"/>
    <axis xyz="1.0 0.0 0.0"/>
  </joint>
  <joint name="Rigid 11" type="fixed">
    <origin rpy="0 0 0" xyz="0.02175 -0.0145 0.006"/>
    <parent link="piper_05_v1_1"/>
    <child link="XM,H-430_idler_Component5_v1__3__1"/>
  </joint>
  <joint name="Revolute 12" type="revolute">
    <limit lower="-1.57" upper="1.57" effort="10" velocity="3"/>
    <origin rpy="0 0 0" xyz="0.028 0.01425 0.013"/>
    <parent link="XM,H-430_idler_Component5_v1__3__1"/>
    <child link="gripper_01_v1_1"/>
    <axis xyz="-0.0 -0.0 1.0"/>
  </joint>
</robot>
